Workbook

Sheet Dashboard
A1: Progress Dashboard
A3: Total Training Days (6 months) | B3: =COUNTIF('6-Month Calendar'!C4:C185,"<>Rest") -> 156
A4: Total Rest Days | B4: =COUNTIF('6-Month Calendar'!C4:C185,"Rest") -> 26
A5: Sessions Completed (Yes) | B5: =COUNTIF('6-Month Calendar'!F4:F185,"Yes") -> 1
A6: Sessions Missed (No) | B6: =COUNTIF('6-Month Calendar'!F4:F185,"No") -> 1
A7: Completion Rate | B7: =IFERROR(B5/B3,0) -> 0.0064102564
A8: Push Days Total | B8: =COUNTIF('6-Month Calendar'!C4:C185,"Push") -> 52
A9: Pull Days Total | B9: =COUNTIF('6-Month Calendar'!C4:C185,"Pull") -> 52
A10: Legs Days Total | B10: =COUNTIF('6-Month Calendar'!C4:C185,"Legs") -> 51

Sheet Plan (PPL Template)
A1: 6-Day PPL Template (Reference)
A3: Day Type | B3: Exercises | C3: Muscle Focus
A4: Push | B4: 1. Incline Barbell Press - 4x8-10 2. Incline DB Press - 4x10 3. Low-to-High Cable Crossover - 4x15 4. Close Grip Bench Press - 4x8-10 5. Overhead Cable Tricep Extension - 4x10-12 6. Rope Pushdown - 4x12-15 | C4: Upper Chest (priority), Triceps - long head + lateral head
A5: Pull | B5: 1. Pull-Ups (weighted/assisted) - 4xMax 2. Wide Grip Lat Pulldown - 4-5x8-15 3. Seated Cable Row (close grip) - 4x10 4. Face Pulls - 4x20 (NON-NEGOTIABLE) 5. Barbell Curl - 4x8-15 6. Reverse Barbell Curl / Wrist Curl - 3x12-20 | C5: Lat Width, Back Thickness, Rear Delts/Posture, Biceps, Forearms
A6: Legs | B6: 1. Barbell Squat - 4x10 2. Leg Press - 4x12 3. Romanian Deadlift - 4x10 4. Standing Calf Raise - 3x20 5. Seated DB Shoulder Press - 4x10 6. Cable Lateral Raise + Reverse Pec Deck - 4x15-20 (NON-NEGOTIABLE) 7. Hanging Leg Raise + Plank - 3x12 / 45s | C6: Quads, Hamstrings, Calves, Shoulders (medial+posterior delt), Core
A7: Rest | B7: Rest Day - Recovery, mobility, sleep, magnesium at night | C7: Recovery

Sheet 6-Month Calendar
A1: Training Calendar - 6 Months (Mon-Sat PPL x2, Sunday Rest)
A3: Date | B3: Weekday | C3: Day Type | D3: Exercises | E3: Muscle Focus | F3: Completed | G3: Notes
A4: 46188 | B4: =TEXT(A4,"DDDD") -> Monday | C4: =CHOOSE(WEEKDAY(A4,2),"Push","Pull","Legs","Push","Pull","Legs","Rest") -> Push | D4: =VLOOKUP(C4,'Plan (PPL Template)'!A4:C7,2,FALSE()) -> 1. Incline Barbell Press - 4x8-10 2. Incline DB Press - 4x10 3. Low-to-High Cable Crossover - 4x15 4. Close Grip Bench Press - 4x8-10 5. Overhead Cable Tricep Extension - 4x10-12 6. Rope Pushdown - 4x12-15 | E4: =VLOOKUP(C4,'Plan (PPL Template)'!A4:C7,3,FALSE()) -> Upper Chest (priority), Triceps - long head + lateral head | F4: No | G4: I have missed monday because I was in my home and also office was closed that day.
A5: 46189 | B5: =TEXT(A5,"DDDD") -> Tuesday | C5: =CHOOSE(WEEKDAY(A5,2),"Push","Pull","Legs","Push","Pull","Legs","Rest") -> Pull | D5: =VLOOKUP(C5,'Plan (PPL Template)'!A4:C7,2,FALSE()) -> 1. Pull-Ups (weighted/assisted) - 4xMax 2. Wide Grip Lat Pulldown - 4-5x8-15 3. Seated Cable Row (close grip) - 4x10 4. Face Pulls - 4x20 (NON-NEGOTIABLE) 5. Barbell Curl - 4x8-15 6. Reverse Barbell Curl / Wrist Curl - 3x12-20 | E5: =VLOOKUP(C5,'Plan (PPL Template)'!A4:C7,3,FALSE()) -> Lat Width, Back Thickness, Rear Delts/Posture, Biceps, Forearms | F5: Yes | G5: I have done this 5 exercise of back and 3 for biceps ack (Lats & Upper Back) Neutral-Grip Lat Pulldown (Mid Range) Close-Grip Lat Pulldown Neutral-Grip Seated Cable Row Single-Arm Chest-Supported High Row (Overhand Grip) Seated Cable Row Biceps Preacher Curl EZ-Bar Curl (assuming by "Curl Bar" you mean an EZ curl bar) Cheat Hammer Curl (or Assisted Cheat Hammer Curl if you're using slight body momentum)
A6: 46190 | B6: =TEXT(A6,"DDDD") -> Wednesday | C6: SHOULDER + LEG | D6: 1. 45 Degree Leg Press - 4x12. 2. Romanian Deadlift - 4x10. 3. Leg Curl - 3x12. 4. Hanging Leg Raise - 2x12-15. 5. Cable Lateral Raise - 4x15-20. 6. Reverse Pec Fly - 4x15. 7. Shoulder Press Machine - 4x10. 8. DB Lateral Raise Burnout - 2x20-25. 9. Cable Crunches - 3x15-20. 10. Reverse Barbell Curl - 3x12-15. 11. Barbell Wrist Curl - 3x20. 12. Farmers Walk - 3x30sec. | E6: =VLOOKUP(C6,'Plan (PPL Template)'!A4:C7,3,FALSE()) -> #N/A | F6: Yes | G6: 1. Leg curl is is not done yet. 2. Reverse Barbell is pending 3. barbell wrist Curl and farmer walk not done
A7: 46191 | B7: =TEXT(A7,"DDDD") -> Thursday | C7: =CHOOSE(WEEKDAY(A7,2),"Push","Pull","Legs","Push","Pull","Legs","Rest") -> Push | D7: =VLOOKUP(C7,'Plan (PPL Template)'!A4:C7,2,FALSE()) -> 1. Incline Barbell Press - 4x8-10 2. Incline DB Press - 4x10 3. Low-to-High Cable Crossover - 4x15 4. Close Grip Bench Press - 4x8-10 5. Overhead Cable Tricep Extension - 4x10-12 6. Rope Pushdown - 4x12-15 | E7: =VLOOKUP(C7,'Plan (PPL Template)'!A4:C7,3,FALSE()) -> Upper Chest (priority), Triceps - long head + lateral head | F7: Yes | G7: Extra: 1. Decline machine press 2. pec dec fly Instead of close grip bench press Extra for tricepe: rope pull down and ABS 1. cruches
A8: 46192 | B8: =TEXT(A8,"DDDD") -> Friday | C8: =CHOOSE(WEEKDAY(A8,2),"Push","Pull","Legs","Push","Pull","Legs","Rest") -> Pull | D8: =VLOOKUP(C8,'Plan (PPL Template)'!A4:C7,2,FALSE()) -> 1. Pull-Ups (weighted/assisted) - 4xMax 2. Wide Grip Lat Pulldown - 4-5x8-15 3. Seated Cable Row (close grip) - 4x10 4. Face Pulls - 4x20 (NON-NEGOTIABLE) 5. Barbell Curl - 4x8-15 6. Reverse Barbell Curl / Wrist Curl - 3x12-20 | E8: =VLOOKUP(C8,'Plan (PPL Template)'!A4:C7,3,FALSE()) -> Lat Width, Back Thickness, Rear Delts/Posture, Biceps, Forearms | F8: Yes | G8: Extra: 1. Wide pull down 2. supported row 3. vertical row 4. Instead of face pull reverse pec fly Biscape: peacher upported curl z bar supported curl Abs: 1. Hanging leg raise 2. upper abs crunches Forearms: 1. wrist curl 2. weight squzee
A9: 46193 | B9: =TEXT(A9,"DDDD") -> Saturday | C9: =CHOOSE(WEEKDAY(A9,2),"Push","Pull","Legs","Push","Pull","Legs","Rest") -> Legs | D9: =VLOOKUP(C9,'Plan (PPL Template)'!A4:C7,2,FALSE()) -> 1. Barbell Squat - 4x10 2. Leg Press - 4x12 3. Romanian Deadlift - 4x10 4. Standing Calf Raise - 3x20 5. Seated DB Shoulder Press - 4x10 6. Cable Lateral Raise + Reverse Pec Deck - 4x15-20 (NON-NEGOTIABLE) 7. Hanging Leg Raise + Plank - 3x12 / 45s | E9: =VLOOKUP(C9,'Plan (PPL Template)'!A4:C7,3,FALSE()) -> Quads, Hamstrings, Calves, Shoulders (medial+posterior delt), Core | F9: Yes
A10: 46194 | B10: =TEXT(A10,"DDDD") -> Sunday | C10: =CHOOSE(WEEKDAY(A10,2),"Push","Pull","Legs","Push","Pull","Legs","Rest") -> Rest | D10: =VLOOKUP(C10,'Plan (PPL Template)'!A4:C7,2,FALSE()) -> Rest Day - Recovery, mobility, sleep, magnesium at night | E10: =VLOOKUP(C10,'Plan (PPL Template)'!A4:C7,3,FALSE()) -> Recovery
A11: 46195 | B11: =TEXT(A11,"DDDD") -> Monday | C11: =CHOOSE(WEEKDAY(A11,2),"Push","Pull","Legs","Push","Pull","Legs","Rest") -> Push | D11: =VLOOKUP(C11,'Plan (PPL Template)'!A4:C7,2,FALSE()) -> 1. Incline Barbell Press - 4x8-10 2. Incline DB Press - 4x10 3. Low-to-High Cable Crossover - 4x15 4. Close Grip Bench Press - 4x8-10 5. Overhead Cable Tricep Extension - 4x10-12 6. Rope Pushdown - 4x12-15 | E11: =VLOOKUP(C11,'Plan (PPL Template)'!A4:C7,3,FALSE()) -> Upper Chest (priority), Triceps - long head + lateral head | F11: Yes
A12: 46196 | B12: =TEXT(A12,"DDDD") -> Tuesday | C12: =CHOOSE(WEEKDAY(A12,2),"Push","Pull","Legs","Push","Pull","Legs","Rest") -> Pull | D12: =VLOOKUP(C12,'Plan (PPL Template)'!A4:C7,2,FALSE()) -> 1. Pull-Ups (weighted/assisted) - 4xMax 2. Wide Grip Lat Pulldown - 4-5x8-15 3. Seated Cable Row (close grip) - 4x10 4. Face Pulls - 4x20 (NON-NEGOTIABLE) 5. Barbell Curl - 4x8-15 6. Reverse Barbell Curl / Wrist Curl - 3x12-20 | E12: =VLOOKUP(C12,'Plan (PPL Template)'!A4:C7,3,FALSE()) -> Lat Width, Back Thickness, Rear Delts/Posture, Biceps, Forearms | F12: Yes
A13: 46197 | B13: =TEXT(A13,"DDDD") -> Wednesday | C13: =CHOOSE(WEEKDAY(A13,2),"Push","Pull","Legs","Push","Pull","Legs","Rest") -> Legs | D13: =VLOOKUP(C13,'Plan (PPL Template)'!A4:C7,2,FALSE()) -> 1. Barbell Squat - 4x10 2. Leg Press - 4x12 3. Romanian Deadlift - 4x10 4. Standing Calf Raise - 3x20 5. Seated DB Shoulder Press - 4x10 6. Cable Lateral Raise + Reverse Pec Deck - 4x15-20 (NON-NEGOTIABLE) 7. Hanging Leg Raise + Plank - 3x12 / 45s | E13: =VLOOKUP(C13,'Plan (PPL Template)'!A4:C7,3,FALSE()) -> Quads, Hamstrings, Calves, Shoulders (medial+posterior delt), Core | F13: Yes
A14: 46198 | B14: =TEXT(A14,"DDDD") -> Thursday | C14: =CHOOSE(WEEKDAY(A14,2),"Push","Pull","Legs","Push","Pull","Legs","Rest") -> Push | D14: =VLOOKUP(C14,'Plan (PPL Template)'!A4:C7,2,FALSE()) -> 1. Incline Barbell Press - 4x8-10 2. Incline DB Press - 4x10 3. Low-to-High Cable Crossover - 4x15 4. Close Grip Bench Press - 4x8-10 5. Overhead Cable Tricep Extension - 4x10-12 6. Rope Pushdown - 4x12-15 | E14: =VLOOKUP(C14,'Plan (PPL Template)'!A4:C7,3,FALSE()) -> Upper Chest (priority), Triceps - long head + lateral head | F14: Yes
A15: 46199 | B15: =TEXT(A15,"DDDD") -> Friday | C15: =CHOOSE(WEEKDAY(A15,2),"Push","Pull","Legs","Push","Pull","Legs","Rest") -> Pull | D15: =VLOOKUP(C15,'Plan (PPL Template)'!A4:C7,2,FALSE()) -> 1. Pull-Ups (weighted/assisted) - 4xMax 2. Wide Grip Lat Pulldown - 4-5x8-15 3. Seated Cable Row (close grip) - 4x10 4. Face Pulls - 4x20 (NON-NEGOTIABLE) 5. Barbell Curl - 4x8-15 6. Reverse Barbell Curl / Wrist Curl - 3x12-20 | E15: =VLOOKUP(C15,'Plan (PPL Template)'!A4:C7,3,FALSE()) -> Lat Width, Back Thickness, Rear Delts/Posture, Biceps, Forearms | F15: Yes
A16: 46200 | B16: =TEXT(A16,"DDDD") -> Saturday | C16: =CHOOSE(WEEKDAY(A16,2),"Push","Pull","Legs","Push","Pull","Legs","Rest") -> Legs | D16: =VLOOKUP(C16,'Plan (PPL Template)'!A4:C7,2,FALSE()) -> 1. Barbell Squat - 4x10 2. Leg Press - 4x12 3. Romanian Deadlift - 4x10 4. Standing Calf Raise - 3x20 5. Seated DB Shoulder Press - 4x10 6. Cable Lateral Raise + Reverse Pec Deck - 4x15-20 (NON-NEGOTIABLE) 7. Hanging Leg Raise + Plank - 3x12 / 45s | E16: =VLOOKUP(C16,'Plan (PPL Template)'!A4:C7,3,FALSE()) -> Quads, Hamstrings, Calves, Shoulders (medial+posterior delt), Core | F16: Yes
A17: 46201 | B17: =TEXT(A17,"DDDD") -> Sunday | C17: =CHOOSE(WEEKDAY(A17,2),"Push","Pull","Legs","Push","Pull","Legs","Rest") -> Rest | D17: =VLOOKUP(C17,'Plan (PPL Template)'!A4:C7,2,FALSE()) -> Rest Day - Recovery, mobility, sleep, magnesium at night | E17: =VLOOKUP(C17,'Plan (PPL Template)'!A4:C7,3,FALSE()) -> Recovery
A18: 46202 | B18: =TEXT(A18,"DDDD") -> Monday | C18: =CHOOSE(WEEKDAY(A18,2),"Push","Pull","Legs","Push","Pull","Legs","Rest") -> Push | D18: =VLOOKUP(C18,'Plan (PPL Template)'!A4:C7,2,FALSE()) -> 1. Incline Barbell Press - 4x8-10 2. Incline DB Press - 4x10 3. Low-to-High Cable Crossover - 4x15 4. Close Grip Bench Press - 4x8-10 5. Overhead Cable Tricep Extension - 4x10-12 6. Rope Pushdown - 4x12-15 | E18: =VLOOKUP(C18,'Plan (PPL Template)'!A4:C7,3,FALSE()) -> Upper Chest (priority), Triceps - long head + lateral head | F18: Yes
A19: 46203 | B19: =TEXT(A19,"DDDD") -> Tuesday | C19: =CHOOSE(WEEKDAY(A19,2),"Push","Pull","Legs","Push","Pull","Legs","Rest") -> Pull | D19: =VLOOKUP(C19,'Plan (PPL Template)'!A4:C7,2,FALSE()) -> 1. Pull-Ups (weighted/assisted) - 4xMax 2. Wide Grip Lat Pulldown - 4-5x8-15 3. Seated Cable Row (close grip) - 4x10 4. Face Pulls - 4x20 (NON-NEGOTIABLE) 5. Barbell Curl - 4x8-15 6. Reverse Barbell Curl / Wrist Curl - 3x12-20 | E19: =VLOOKUP(C19,'Plan (PPL Template)'!A4:C7,3,FALSE()) -> Lat Width, Back Thickness, Rear Delts/Posture, Biceps, Forearms | F19: Yes
A20: 46204 | B20: =TEXT(A20,"DDDD") -> Wednesday | C20: =CHOOSE(WEEKDAY(A20,2),"Push","Pull","Legs","Push","Pull","Legs","Rest") -> Legs | D20: =VLOOKUP(C20,'Plan (PPL Template)'!A4:C7,2,FALSE()) -> 1. Barbell Squat - 4x10 2. Leg Press - 4x12 3. Romanian Deadlift - 4x10 4. Standing Calf Raise - 3x20 5. Seated DB Shoulder Press - 4x10 6. Cable Lateral Raise + Reverse Pec Deck - 4x15-20 (NON-NEGOTIABLE) 7. Hanging Leg Raise + Plank - 3x12 / 45s | E20: =VLOOKUP(C20,'Plan (PPL Template)'!A4:C7,3,FALSE()) -> Quads, Hamstrings, Calves, Shoulders (medial+posterior delt), Core | F20: Yes
A21: 46205 | B21: =TEXT(A21,"DDDD") -> Thursday | C21: =CHOOSE(WEEKDAY(A21,2),"Push","Pull","Legs","Push","Pull","Legs","Rest") -> Push | D21: =VLOOKUP(C21,'Plan (PPL Template)'!A4:C7,2,FALSE()) -> 1. Incline Barbell Press - 4x8-10 2. Incline DB Press - 4x10 3. Low-to-High Cable Crossover - 4x15 4. Close Grip Bench Press - 4x8-10 5. Overhead Cable Tricep Extension - 4x10-12 6. Rope Pushdown - 4x12-15 | E21: =VLOOKUP(C21,'Plan (PPL Template)'!A4:C7,3,FALSE()) -> Upper Chest (priority), Triceps - long head + lateral head | F21: Yes
A22: 46206 | B22: =TEXT(A22,"DDDD") -> Friday | C22: =CHOOSE(WEEKDAY(A22,2),"Push","Pull","Legs","Push","Pull","Legs","Rest") -> Pull | D22: =VLOOKUP(C22,'Plan (PPL Template)'!A4:C7,2,FALSE()) -> 1. Pull-Ups (weighted/assisted) - 4xMax 2. Wide Grip Lat Pulldown - 4-5x8-15 3. Seated Cable Row (close grip) - 4x10 4. Face Pulls - 4x20 (NON-NEGOTIABLE) 5. Barbell Curl - 4x8-15 6. Reverse Barbell Curl / Wrist Curl - 3x12-20 | E22: =VLOOKUP(C22,'Plan (PPL Template)'!A4:C7,3,FALSE()) -> Lat Width, Back Thickness, Rear Delts/Posture, Biceps, Forearms | F22: Yes
A23: 46207 | B23: =TEXT(A23,"DDDD") -> Saturday | C23: =CHOOSE(WEEKDAY(A23,2),"Push","Pull","Legs","Push","Pull","Legs","Rest") -> Legs | D23: =VLOOKUP(C23,'Plan (PPL Template)'!A4:C7,2,FALSE()) -> 1. Barbell Squat - 4x10 2. Leg Press - 4x12 3. Romanian Deadlift - 4x10 4. Standing Calf Raise - 3x20 5. Seated DB Shoulder Press - 4x10 6. Cable Lateral Raise + Reverse Pec Deck - 4x15-20 (NON-NEGOTIABLE) 7. Hanging Leg Raise + Plank - 3x12 / 45s | E23: =VLOOKUP(C23,'Plan (PPL Template)'!A4:C7,3,FALSE()) -> Quads, Hamstrings, Calves, Shoulders (medial+posterior delt), Core | F23: Yes
A24: 46208 | B24: =TEXT(A24,"DDDD") -> Sunday | C24: =CHOOSE(WEEKDAY(A24,2),"Push","Pull","Legs","Push","Pull","Legs","Rest") -> Rest | D24: =VLOOKUP(C24,'Plan (PPL Template)'!A4:C7,2,FALSE()) -> Rest Day - Recovery, mobility, sleep, magnesium at night | E24: =VLOOKUP(C24,'Plan (PPL Template)'!A4:C7,3,FALSE()) -> Recovery
A25: 46209 | B25: =TEXT(A25,"DDDD") -> Monday | C25: =CHOOSE(WEEKDAY(A25,2),"Push","Pull","Legs","Push","Pull","Legs","Rest") -> Push | D25: =VLOOKUP(C25,'Plan (PPL Template)'!A4:C7,2,FALSE()) -> 1. Incline Barbell Press - 4x8-10 2. Incline DB Press - 4x10 3. Low-to-High Cable Crossover - 4x15 4. Close Grip Bench Press - 4x8-10 5. Overhead Cable Tricep Extension - 4x10-12 6. Rope Pushdown - 4x12-15 | E25: =VLOOKUP(C25,'Plan (PPL Template)'!A4:C7,3,FALSE()) -> Upper Chest (priority), Triceps - long head + lateral head
A26: 46210 | B26: =TEXT(A26,"DDDD") -> Tuesday | C26: =CHOOSE(WEEKDAY(A26,2),"Push","Pull","Legs","Push","Pull","Legs","Rest") -> Pull | D26: =VLOOKUP(C26,'Plan (PPL Template)'!A4:C7,2,FALSE()) -> 1. Pull-Ups (weighted/assisted) - 4xMax 2. Wide Grip Lat Pulldown - 4-5x8-15 3. Seated Cable Row (close grip) - 4x10 4. Face Pulls - 4x20 (NON-NEGOTIABLE) 5. Barbell Curl - 4x8-15 6. Reverse Barbell Curl / Wrist Curl - 3x12-20 | E26: =VLOOKUP(C26,'Plan (PPL Template)'!A4:C7,3,FALSE()) -> Lat Width, Back Thickness, Rear Delts/Posture, Biceps, Forearms
A27: 46211 | B27: =TEXT(A27,"DDDD") -> Wednesday | C27: =CHOOSE(WEEKDAY(A27,2),"Push","Pull","Legs","Push","Pull","Legs","Rest") -> Legs | D27: =VLOOKUP(C27,'Plan (PPL Template)'!A4:C7,2,FALSE()) -> 1. Barbell Squat - 4x10 2. Leg Press - 4x12 3. Romanian Deadlift - 4x10 4. Standing Calf Raise - 3x20 5. Seated DB Shoulder Press - 4x10 6. Cable Lateral Raise + Reverse Pec Deck - 4x15-20 (NON-NEGOTIABLE) 7. Hanging Leg Raise + Plank - 3x12 / 45s | E27: =VLOOKUP(C27,'Plan (PPL Template)'!A4:C7,3,FALSE()) -> Quads, Hamstrings, Calves, Shoulders (medial+posterior delt), Core
A28: 46212 | B28: =TEXT(A28,"DDDD") -> Thursday | C28: =CHOOSE(WEEKDAY(A28,2),"Push","Pull","Legs","Push","Pull","Legs","Rest") -> Push | D28: =VLOOKUP(C28,'Plan (PPL Template)'!A4:C7,2,FALSE()) -> 1. Incline Barbell Press - 4x8-10 2. Incline DB Press - 4x10 3. Low-to-High Cable Crossover - 4x15 4. Close Grip Bench Press - 4x8-10 5. Overhead Cable Tricep Extension - 4x10-12 6. Rope Pushdown - 4x12-15 | E28: =VLOOKUP(C28,'Plan (PPL Template)'!A4:C7,3,FALSE()) -> Upper Chest (priority), Triceps - long head + lateral head
A29: 46213 | B29: =TEXT(A29,"DDDD") -> Friday | C29: =CHOOSE(WEEKDAY(A29,2),"Push","Pull","Legs","Push","Pull","Legs","Rest") -> Pull | D29: =VLOOKUP(C29,'Plan (PPL Template)'!A4:C7,2,FALSE()) -> 1. Pull-Ups (weighted/assisted) - 4xMax 2. Wide Grip Lat Pulldown - 4-5x8-15 3. Seated Cable Row (close grip) - 4x10 4. Face Pulls - 4x20 (NON-NEGOTIABLE) 5. Barbell Curl - 4x8-15 6. Reverse Barbell Curl / Wrist Curl - 3x12-20 | E29: =VLOOKUP(C29,'Plan (PPL Template)'!A4:C7,3,FALSE()) -> Lat Width, Back Thickness, Rear Delts/Posture, Biceps, Forearms
A30: 46214 | B30: =TEXT(A30,"DDDD") -> Saturday | C30: =CHOOSE(WEEKDAY(A30,2),"Push","Pull","Legs","Push","Pull","Legs","Rest") -> Legs | D30: =VLOOKUP(C30,'Plan (PPL Template)'!A4:C7,2,FALSE()) -> 1. Barbell Squat - 4x10 2. Leg Press - 4x12 3. Romanian Deadlift - 4x10 4. Standing Calf Raise - 3x20 5. Seated DB Shoulder Press - 4x10 6. Cable Lateral Raise + Reverse Pec Deck - 4x15-20 (NON-NEGOTIABLE) 7. Hanging Leg Raise + Plank - 3x12 / 45s | E30: =VLOOKUP(C30,'Plan (PPL Template)'!A4:C7,3,FALSE()) -> Quads, Hamstrings, Calves, Shoulders (medial+posterior delt), Core
A31: 46215 | B31: =TEXT(A31,"DDDD") -> Sunday | C31: =CHOOSE(WEEKDAY(A31,2),"Push","Pull","Legs","Push","Pull","Legs","Rest") -> Rest | D31: =VLOOKUP(C31,'Plan (PPL Template)'!A4:C7,2,FALSE()) -> Rest Day - Recovery, mobility, sleep, magnesium at night | E31: =VLOOKUP(C31,'Plan (PPL Template)'!A4:C7,3,FALSE()) -> Recovery
A32: 46216 | B32: =TEXT(A32,"DDDD") -> Monday | C32: =CHOOSE(WEEKDAY(A32,2),"Push","Pull","Legs","Push","Pull","Legs","Rest") -> Push | D32: =VLOOKUP(C32,'Plan (PPL Template)'!A4:C7,2,FALSE()) -> 1. Incline Barbell Press - 4x8-10 2. Incline DB Press - 4x10 3. Low-to-High Cable Crossover - 4x15 4. Close Grip Bench Press - 4x8-10 5. Overhead Cable Tricep Extension - 4x10-12 6. Rope Pushdown - 4x12-15 | E32: =VLOOKUP(C32,'Plan (PPL Template)'!A4:C7,3,FALSE()) -> Upper Chest (priority), Triceps - long head + lateral head
A33: 46217 | B33: =TEXT(A33,"DDDD") -> Tuesday | C33: =CHOOSE(WEEKDAY(A33,2),"Push","Pull","Legs","Push","Pull","Legs","Rest") -> Pull | D33: =VLOOKUP(C33,'Plan (PPL Template)'!A4:C7,2,FALSE()) -> 1. Pull-Ups (weighted/assisted) - 4xMax 2. Wide Grip Lat Pulldown - 4-5x8-15 3. Seated Cable Row (close grip) - 4x10 4. Face Pulls - 4x20 (NON-NEGOTIABLE) 5. Barbell Curl - 4x8-15 6. Reverse Barbell Curl / Wrist Curl - 3x12-20 | E33: =VLOOKUP(C33,'Plan (PPL Template)'!A4:C7,3,FALSE()) -> Lat Width, Back Thickness, Rear Delts/Posture, Biceps, Forearms
A34: 46218 | B34: =TEXT(A34,"DDDD") -> Wednesday | C34: =CHOOSE(WEEKDAY(A34,2),"Push","Pull","Legs","Push","Pull","Legs","Rest") -> Legs | D34: =VLOOKUP(C34,'Plan (PPL Template)'!A4:C7,2,FALSE()) -> 1. Barbell Squat - 4x10 2. Leg Press - 4x12 3. Romanian Deadlift - 4x10 4. Standing Calf Raise - 3x20 5. Seated DB Shoulder Press - 4x10 6. Cable Lateral Raise + Reverse Pec Deck - 4x15-20 (NON-NEGOTIABLE) 7. Hanging Leg Raise + Plank - 3x12 / 45s | E34: =VLOOKUP(C34,'Plan (PPL Template)'!A4:C7,3,FALSE()) -> Quads, Hamstrings, Calves, Shoulders (medial+posterior delt), Core
A35: 46219 | B35: =TEXT(A35,"DDDD") -> Thursday | C35: =CHOOSE(WEEKDAY(A35,2),"Push","Pull","Legs","Push","Pull","Legs","Rest") -> Push | D35: =VLOOKUP(C35,'Plan (PPL Template)'!A4:C7,2,FALSE()) -> 1. Incline Barbell Press - 4x8-10 2. Incline DB Press - 4x10 3. Low-to-High Cable Crossover - 4x15 4. Close Grip Bench Press - 4x8-10 5. Overhead Cable Tricep Extension - 4x10-12 6. Rope Pushdown - 4x12-15 | E35: =VLOOKUP(C35,'Plan (PPL Template)'!A4:C7,3,FALSE()) -> Upper Chest (priority), Triceps - long head + lateral head
A36: 46220 | B36: =TEXT(A36,"DDDD") -> Friday | C36: =CHOOSE(WEEKDAY(A36,2),"Push","Pull","Legs","Push","Pull","Legs","Rest") -> Pull | D36: =VLOOKUP(C36,'Plan (PPL Template)'!A4:C7,2,FALSE()) -> 1. Pull-Ups (weighted/assisted) - 4xMax 2. Wide Grip Lat Pulldown - 4-5x8-15 3. Seated Cable Row (close grip) - 4x10 4. Face Pulls - 4x20 (NON-NEGOTIABLE) 5. Barbell Curl - 4x8-15 6. Reverse Barbell Curl / Wrist Curl - 3x12-20 | E36: =VLOOKUP(C36,'Plan (PPL Template)'!A4:C7,3,FALSE()) -> Lat Width, Back Thickness, Rear Delts/Posture, Biceps, Forearms
A37: 46221 | B37: =TEXT(A37,"DDDD") -> Saturday | C37: =CHOOSE(WEEKDAY(A37,2),"Push","Pull","Legs","Push","Pull","Legs","Rest") -> Legs | D37: =VLOOKUP(C37,'Plan (PPL Template)'!A4:C7,2,FALSE()) -> 1. Barbell Squat - 4x10 2. Leg Press - 4x12 3. Romanian Deadlift - 4x10 4. Standing Calf Raise - 3x20 5. Seated DB Shoulder Press - 4x10 6. Cable Lateral Raise + Reverse Pec Deck - 4x15-20 (NON-NEGOTIABLE) 7. Hanging Leg Raise + Plank - 3x12 / 45s | E37: =VLOOKUP(C37,'Plan (PPL Template)'!A4:C7,3,FALSE()) -> Quads, Hamstrings, Calves, Shoulders (medial+posterior delt), Core
A38: 46222 | B38: =TEXT(A38,"DDDD") -> Sunday | C38: =CHOOSE(WEEKDAY(A38,2),"Push","Pull","Legs","Push","Pull","Legs","Rest") -> Rest | D38: =VLOOKUP(C38,'Plan (PPL Template)'!A4:C7,2,FALSE()) -> Rest Day - Recovery, mobility, sleep, magnesium at night | E38: =VLOOKUP(C38,'Plan (PPL Template)'!A4:C7,3,FALSE()) -> Recovery
A39: 46223 | B39: =TEXT(A39,"DDDD") -> Monday | C39: =CHOOSE(WEEKDAY(A39,2),"Push","Pull","Legs","Push","Pull","Legs","Rest") -> Push | D39: =VLOOKUP(C39,'Plan (PPL Template)'!A4:C7,2,FALSE()) -> 1. Incline Barbell Press - 4x8-10 2. Incline DB Press - 4x10 3. Low-to-High Cable Crossover - 4x15 4. Close Grip Bench Press - 4x8-10 5. Overhead Cable Tricep Extension - 4x10-12 6. Rope Pushdown - 4x12-15 | E39: =VLOOKUP(C39,'Plan (PPL Template)'!A4:C7,3,FALSE()) -> Upper Chest (priority), Triceps - long head + lateral head
A40: 46224 | B40: =TEXT(A40,"DDDD") -> Tuesday | C40: =CHOOSE(WEEKDAY(A40,2),"Push","Pull","Legs","Push","Pull","Legs","Rest") -> Pull | D40: =VLOOKUP(C40,'Plan (PPL Template)'!A4:C7,2,FALSE()) -> 1. Pull-Ups (weighted/assisted) - 4xMax 2. Wide Grip Lat Pulldown - 4-5x8-15 3. Seated Cable Row (close grip) - 4x10 4. Face Pulls - 4x20 (NON-NEGOTIABLE) 5. Barbell Curl - 4x8-15 6. Reverse Barbell Curl / Wrist Curl - 3x12-20 | E40: =VLOOKUP(C40,'Plan (PPL Template)'!A4:C7,3,FALSE()) -> Lat Width, Back Thickness, Rear Delts/Posture, Biceps, Forearms
A41: 46225 | B41: =TEXT(A41,"DDDD") -> Wednesday | C41: =CHOOSE(WEEKDAY(A41,2),"Push","Pull","Legs","Push","Pull","Legs","Rest") -> Legs | D41: =VLOOKUP(C41,'Plan (PPL Template)'!A4:C7,2,FALSE()) -> 1. Barbell Squat - 4x10 2. Leg Press - 4x12 3. Romanian Deadlift - 4x10 4. Standing Calf Raise - 3x20 5. Seated DB Shoulder Press - 4x10 6. Cable Lateral Raise + Reverse Pec Deck - 4x15-20 (NON-NEGOTIABLE) 7. Hanging Leg Raise + Plank - 3x12 / 45s | E41: =VLOOKUP(C41,'Plan (PPL Template)'!A4:C7,3,FALSE()) -> Quads, Hamstrings, Calves, Shoulders (medial+posterior delt), Core
...
